Workbook

Sheet Inventory
A1: THE KITCHEN TCG — INVENTORY (Source of Truth)
A2: Publish this tab as CSV and sync into the app. Includes avg purchase price for P&L reference.
A4: product_name | B4: set_name | C4: short_name | D4: item_type | E4: quantity | F4: sticker_price | G4: avg_purchase_price | H4: image_url | I4: tcgplayer_url | J4: alt_url | K4: cardladder_url
A5: Full product name | B5: Set / series | C5: Short name shown in app | D5: Sealed | Singles | Graded | E5: Units in stock | F5: Sell price (auto-loads to app) | G5: Avg cost from Purchase History tab | H5: Direct image URL | I5: TCGPlayer URL — Sealed & Singles | J5: Alt.xyz URL — Graded only | K5: Card Ladder URL — Graded only
A6: ★ Gold=all Blue=Sealed/Singles Amber=Graded Green=calculated from Purchase History (do not edit manually)
A7: 151 Pokemon Center Elite Trainer Box Case | B7: 151 | C7: 151 PC ETB Case | D7: Sealed | E7: 2 | F7: 2000 | G7: =IFERROR(AVERAGEIF('Purchase History'!B:B,C7,'Purchase History'!E:E),"") | H7: https://tcgplayer-cdn.tcgplayer.com/product/528030_in_1000x1000.jpg | I7: https://www.tcgplayer.com/product/528030/pokemon-sv-scarlet-and-violet-151-151-pokemon-center-elite-trainer-box-exclusive-case?Language=English&page=1
A8: Hidden Fates Elite Trainer Box Case | B8: Hidden Fates | C8: Hidden Fates ETB Case | D8: Sealed | E8: 2 | F8: 1990 | G8: =IFERROR(AVERAGEIF('Purchase History'!B:B,C8,'Purchase History'!E:E),"") | H8: https://tcgplayer-cdn.tcgplayer.com/product/648466_in_1000x1000.jpg | I8: https://www.tcgplayer.com/product/648466/pokemon-hidden-fates-hidden-fates-elite-trainer-box-case?Language=English&page=1
A9: 151 Elite Trainer Box Case | B9: 151 | C9: 151 ETB Case | D9: Sealed | E9: 2 | F9: 1980 | G9: =IFERROR(AVERAGEIF('Purchase History'!B:B,C9,'Purchase History'!E:E),"") | H9: https://tcgplayer-cdn.tcgplayer.com/product/506640_in_1000x1000.jpg | I9: https://www.tcgplayer.com/product/506640/pokemon-sv-scarlet-and-violet-151-151-elite-trainer-box-case?Language=English&page=1
A10: Evolving Skies Elite Trainer Box Case | B10: Evolving Skies | C10: Evolving Skies ETB Case | D10: Sealed | E10: 2 | F10: 1970 | G10: =IFERROR(AVERAGEIF('Purchase History'!B:B,C10,'Purchase History'!E:E),"") | H10: https://tcgplayer-cdn.tcgplayer.com/product/243722_in_1000x1000.jpg | I10: https://www.tcgplayer.com/product/243722/pokemon-swsh07-evolving-skies-evolving-skies-elite-trainer-box-case?Language=English&page=1
A11: Fusion Strike Elite Trainer Box Case | B11: Fusion Strike | C11: Fusion Strike ETB Case | D11: Sealed | E11: 2 | F11: 1960 | G11: =IFERROR(AVERAGEIF('Purchase History'!B:B,C11,'Purchase History'!E:E),"") | H11: https://tcgplayer-cdn.tcgplayer.com/product/256271_in_1000x1000.jpg | I11: https://www.tcgplayer.com/product/256271/pokemon-swsh08-fusion-strike-fusion-strike-elite-trainer-box-case?Language=English&page=1
A12: Paldean Fates Elite Trainer Box Case | B12: Paldean Fates | C12: Paldean Fates ETB Case | D12: Sealed | E12: 2 | F12: 1950 | G12: =IFERROR(AVERAGEIF('Purchase History'!B:B,C12,'Purchase History'!E:E),"") | H12: https://tcgplayer-cdn.tcgplayer.com/product/530700_in_1000x1000.jpg | I12: https://www.tcgplayer.com/product/530700/pokemon-sv-paldean-fates-paldean-fates-elite-trainer-box-case?Language=English&page=1
A13: Celebrations Elite Trainer Box Case | B13: Celebrations | C13: Celebrations ETB Case | D13: Sealed | E13: 2 | F13: 1940 | G13: =IFERROR(AVERAGEIF('Purchase History'!B:B,C13,'Purchase History'!E:E),"") | H13: https://tcgplayer-cdn.tcgplayer.com/product/251895_in_1000x1000.jpg | I13: https://www.tcgplayer.com/product/251895/pokemon-celebrations-celebrations-elite-trainer-box-case?Language=English&page=1
A14: Crown Zenith Elite Trainer Box Case | B14: Crown Zenith | C14: Crown Zenith ETB Case | D14: Sealed | E14: 2 | F14: 1930 | G14: =IFERROR(AVERAGEIF('Purchase History'!B:B,C14,'Purchase History'!E:E),"") | H14: https://tcgplayer-cdn.tcgplayer.com/product/453471_in_1000x1000.jpg | I14: https://www.tcgplayer.com/product/453471/pokemon-crown-zenith-crown-zenith-elite-trainer-box-case?Language=English&page=1
A15: Evolving Skies Booster Box | B15: Evolving Skies | C15: Evolving Skies Booster Box | D15: Sealed | E15: 2 | F15: 1920 | G15: =IFERROR(AVERAGEIF('Purchase History'!B:B,C15,'Purchase History'!E:E),"") | H15: https://tcgplayer-cdn.tcgplayer.com/product/242436_in_1000x1000.jpg | I15: https://www.tcgplayer.com/product/242436/pokemon-swsh07-evolving-skies-evolving-skies-booster-box?Language=English&page=1
A16: Prismatic Evolutions Pokemon Center Elite Trainer Box Case | B16: Prismatic Evolutions | C16: Prismatic Evolutions PC ETB Case | D16: Sealed | E16: 2 | F16: 1910 | G16: =IFERROR(AVERAGEIF('Purchase History'!B:B,C16,'Purchase History'!E:E),"") | H16: https://tcgplayer-cdn.tcgplayer.com/product/600697_in_1000x1000.jpg | I16: https://www.tcgplayer.com/product/600697/pokemon-sv-prismatic-evolutions-prismatic-evolutions-pokemon-center-elite-trainer-box-exclusive-case?Language=English&page=1
A17: Crown Zenith Pokemon Center Elite Trainer Box Plus Case | B17: Crown Zenith | C17: Crown Zenith PC ETB Plus Case | D17: Sealed | E17: 2 | F17: 1900 | G17: =IFERROR(AVERAGEIF('Purchase History'!B:B,C17,'Purchase History'!E:E),"") | H17: https://tcgplayer-cdn.tcgplayer.com/product/454247_in_1000x1000.jpg | I17: https://www.tcgplayer.com/product/454247/pokemon-crown-zenith-crown-zenith-pokemon-center-elite-trainer-box-plus-case?Language=English&page=1
A18: 151 Booster Bundle Display | B18: 151 | C18: 151 Booster Bundle Display | D18: Sealed | E18: 2 | F18: 1890 | G18: =IFERROR(AVERAGEIF('Purchase History'!B:B,C18,'Purchase History'!E:E),"") | H18: https://tcgplayer-cdn.tcgplayer.com/product/513405_in_1000x1000.jpg | I18: https://www.tcgplayer.com/product/513405/pokemon-sv-scarlet-and-violet-151-151-booster-bundle-display?Language=English&page=1
A19: Prismatic Evolutions Elite Trainer Box Case | B19: Prismatic Evolutions | C19: Prismatic Evolutions ETB Case | D19: Sealed | E19: 2 | F19: 1880 | G19: =IFERROR(AVERAGEIF('Purchase History'!B:B,C19,'Purchase History'!E:E),"") | H19: https://tcgplayer-cdn.tcgplayer.com/product/598487_in_1000x1000.jpg | I19: https://www.tcgplayer.com/product/598487/pokemon-sv-prismatic-evolutions-prismatic-evolutions-elite-trainer-box-case?Language=English&page=1
A20: Sword & Shield Charizard Ultra Premium Collection Case | B20: Lost Origin | C20: Sword & Shield Charizard UPC Case | D20: Sealed | E20: 2 | F20: 1870 | G20: =IFERROR(AVERAGEIF('Purchase History'!B:B,C20,'Purchase History'!E:E),"") | H20: https://tcgplayer-cdn.tcgplayer.com/product/454377_in_1000x1000.jpg | I20: https://www.tcgplayer.com/product/454377/pokemon-swsh11-lost-origin-sword-and-shield-ultra-premium-collection-charizard-case?Language=English&page=1
A21: Obsidian Flames Elite Trainer Box Case | B21: Obsidian Flames | C21: Obsidian Flames ETB Case | D21: Sealed | E21: 2 | F21: 1860 | G21: =IFERROR(AVERAGEIF('Purchase History'!B:B,C21,'Purchase History'!E:E),"") | H21: https://tcgplayer-cdn.tcgplayer.com/product/501265_in_1000x1000.jpg | I21: https://www.tcgplayer.com/product/501265/pokemon-sv03-obsidian-flames-obsidian-flames-elite-trainer-box-case?Language=English&page=1
A22: Paldea Evolved Elite Trainer Box Case | B22: Paldea Evolved | C22: Paldea Evolved ETB Case | D22: Sealed | E22: 2 | F22: 1850 | G22: =IFERROR(AVERAGEIF('Purchase History'!B:B,C22,'Purchase History'!E:E),"") | H22: https://tcgplayer-cdn.tcgplayer.com/product/496911_in_1000x1000.jpg | I22: https://www.tcgplayer.com/product/496911/pokemon-sv02-paldea-evolved-paldea-evolved-elite-trainer-box-case?Language=English&page=1
A23: Eevee Heroes Set Gym Box (JP) | B23: Eevee Heroes | C23: Eevee Heroes Set Gym Box (JP) | D23: Sealed | E23: 2 | F23: 1840 | G23: =IFERROR(AVERAGEIF('Purchase History'!B:B,C23,'Purchase History'!E:E),"") | H23: https://tcgplayer-cdn.tcgplayer.com/product/608794_in_1000x1000.jpg | I23: https://www.tcgplayer.com/product/608794/pokemon-japan-s6a-eevee-heroes-eevee-heroes-gym-box?Language=all&page=1
A24: Lost Origin Elite Trainer Box Case | B24: Lost Origin | C24: Lost Origin ETB Case | D24: Sealed | E24: 2 | F24: 1830 | G24: =IFERROR(AVERAGEIF('Purchase History'!B:B,C24,'Purchase History'!E:E),"") | H24: https://tcgplayer-cdn.tcgplayer.com/product/278796_in_1000x1000.jpg | I24: https://www.tcgplayer.com/product/278796/pokemon-swsh11-lost-origin-lost-origin-elite-trainer-box-case?Language=all&page=1
A25: Journey Together Enhanced Booster Box Case | B25: Journey Together | C25: Journey Together Enhanced Booster Box Case | D25: Sealed | E25: 2 | F25: 1820 | G25: =IFERROR(AVERAGEIF('Purchase History'!B:B,C25,'Purchase History'!E:E),"") | H25: https://tcgplayer-cdn.tcgplayer.com/product/625583_in_1000x1000.jpg | I25: https://www.tcgplayer.com/product/625583/pokemon-sv09-journey-together-journey-together-enhanced-booster-box-case?Language=all&page=1
A26: Cosmic Eclipse Elite Trainer Box | B26: Cosmic Eclipse | C26: Cosmic Eclipse ETB | D26: Sealed | E26: 2 | F26: 1810 | G26: =IFERROR(AVERAGEIF('Purchase History'!B:B,C26,'Purchase History'!E:E),"") | H26: https://tcgplayer-cdn.tcgplayer.com/product/199308_in_1000x1000.jpg | I26: https://www.tcgplayer.com/product/199308/pokemon-sm-cosmic-eclipse-cosmic-eclipse-elite-trainer-box?Language=English&page=1
A27: 151 Pokemon Center Elite Trainer Box | B27: 151 | C27: 151 PC ETB | D27: Sealed | E27: 2 | F27: 1800 | G27: =IFERROR(AVERAGEIF('Purchase History'!B:B,C27,'Purchase History'!E:E),"") | H27: https://tcgplayer-cdn.tcgplayer.com/product/501999_in_1000x1000.jpg | I27: https://www.tcgplayer.com/product/501999/pokemon-sv-scarlet-and-violet-151-151-pokemon-center-elite-trainer-box-exclusive?Language=all&page=1
A28: Ascended Heroes Elite Trainer Box Case | B28: Ascended Heroes | C28: Ascended Heroes ETB Case | D28: Sealed | E28: 2 | F28: 1790 | G28: =IFERROR(AVERAGEIF('Purchase History'!B:B,C28,'Purchase History'!E:E),"") | H28: https://tcgplayer-cdn.tcgplayer.com/product/668496_in_1000x1000.jpg | I28: https://www.tcgplayer.com/product/679558/pokemon-me-ascended-heroes-ascended-heroes-elite-trainer-box-case?Language=all&page=1
A29: Paradox Rift Elite Trainer Box Case | B29: Paradox Rift | C29: Paradox Rift ETB Case | D29: Sealed | E29: 2 | F29: 1780 | G29: =IFERROR(AVERAGEIF('Purchase History'!B:B,C29,'Purchase History'!E:E),"") | H29: https://tcgplayer-cdn.tcgplayer.com/product/512834_in_1000x1000.jpg | I29: https://www.tcgplayer.com/product/513511/pokemon-sv04-paradox-rift-paradox-rift-elite-trainer-box-case?Language=all&page=1
A30: Silver Tempest Elite Trainer Box Case | B30: Silver Tempest | C30: Silver Tempest ETB Case | D30: Sealed | E30: 2 | F30: 1770 | G30: =IFERROR(AVERAGEIF('Purchase History'!B:B,C30,'Purchase History'!E:E),"") | H30: https://tcgplayer-cdn.tcgplayer.com/product/285777_in_1000x1000.jpg | I30: https://www.tcgplayer.com/product/285777/pokemon-swsh12-silver-tempest-silver-tempest-elite-trainer-box-case?Language=all&page=1
A31: Brilliant Stars Elite Trainer Box Case | B31: Brilliant Stars | C31: Brilliant Stars ETB Case | D31: Sealed | E31: 2 | F31: 1760 | G31: =IFERROR(AVERAGEIF('Purchase History'!B:B,C31,'Purchase History'!E:E),"") | H31: https://tcgplayer-cdn.tcgplayer.com/product/264269_in_1000x1000.jpg | I31: https://www.tcgplayer.com/product/264269/pokemon-swsh09-brilliant-stars-brilliant-stars-elite-trainer-box-case?Language=all&page=1
A32: Hidden Fates Ultra Premium Collection | B32: Hidden Fates | C32: Hidden Fates UPC | D32: Sealed | E32: 2 | F32: 1750 | H32: https://tcgplayer-cdn.tcgplayer.com/product/199466_in_1000x1000.jpg | I32: https://www.tcgplayer.com/product/199466/pokemon-hidden-fates-hidden-fates-ultra-premium-collection?page=1&Language=all
A33: Black Bolt Elite Trainer Box Case | B33: Black Bolt | C33: Black Bolt ETB Case | D33: Sealed | E33: 2 | F33: 1740 | H33: https://tcgplayer-cdn.tcgplayer.com/product/630690_in_1000x1000.jpg | I33: https://www.tcgplayer.com/product/630690/pokemon-sv-black-bolt-black-bolt-elite-trainer-box-case?Language=all&page=1
A34: Lost Origin Pokemon Center Elite Trainer Box Case | B34: Lost Origin | C34: Lost Origin PC ETB Case | D34: Sealed | E34: 2 | F34: 1730 | H34: https://tcgplayer-cdn.tcgplayer.com/product/277336_in_1000x1000.jpg | I34: https://www.tcgplayer.com/product/652759/pokemon-swsh11-lost-origin-lost-origin-pokemon-center-elite-trainer-box-case-exclusive?Language=all&page=1
A35: White Flare Elite Trainer Box Case | B35: White Flare | C35: White Flare ETB Case | D35: Sealed | E35: 2 | F35: 1720 | H35: https://tcgplayer-cdn.tcgplayer.com/product/630693_in_1000x1000.jpg | I35: https://www.tcgplayer.com/product/630693/pokemon-sv-white-flare-white-flare-elite-trainer-box-case?Language=all&page=1
A36: Phantasmal Flames Elite Trainer Box Case | B36: Phantasmal Flames | C36: Phantasmal Flames ETB Case | D36: Sealed | E36: 2 | F36: 1710 | H36: https://tcgplayer-cdn.tcgplayer.com/product/654170_in_1000x1000.jpg | I36: https://www.tcgplayer.com/product/654170/pokemon-me02-phantasmal-flames-phantasmal-flames-elite-trainer-box-case?Language=all&page=1
A37: Shining Legends Elite Trainer Box | B37: Shining Legends | C37: Shining Legends ETB | D37: Sealed | E37: 2 | F37: 1700 | H37: https://tcgplayer-cdn.tcgplayer.com/product/145847_in_1000x1000.jpg | I37: https://www.tcgplayer.com/product/145847/pokemon-shining-legends-shining-legends-elite-trainer-box?Language=English&page=1
A38: 151 Ultra-Premium Collection | B38: 151 | C38: 151 UPC | D38: Sealed | E38: 2 | F38: 1690 | H38: https://tcgplayer-cdn.tcgplayer.com/product/502005_in_1000x1000.jpg | I38: https://www.tcgplayer.com/product/502005/pokemon-sv-scarlet-and-violet-151-151-ultra-premium-collection?Language=English&page=1
A39: Stellar Crown Elite Trainer Box Case | B39: Stellar Crown | C39: Stellar Crown ETB Case | D39: Sealed | E39: 2 | F39: 1680 | H39: https://tcgplayer-cdn.tcgplayer.com/product/559102_in_1000x1000.jpg | I39: https://www.tcgplayer.com/product/559102/pokemon-sv07-stellar-crown-stellar-crown-elite-trainer-box-case?Language=all&page=1
A40: Mega Evolution Elite Trainer Box Case | B40: Mega Evolution | C40: Mega Evolution ETB Case | D40: Sealed | E40: 2 | F40: 1670 | H40: https://tcgplayer-cdn.tcgplayer.com/product/648394_in_1000x1000.jpg | I40: https://www.tcgplayer.com/product/644727/pokemon-me01-mega-evolution-mega-evolution-elite-trainer-box-case?Language=all&page=1
A41: Stellar Crown Pokemon Center Elite Trainer Box Case | B41: Stellar Crown | C41: Stellar Crown PC ETB Case | D41: Sealed | E41: 2 | F41: 1660 | H41: https://tcgplayer-cdn.tcgplayer.com/product/557363_in_1000x1000.jpg | I41: https://www.tcgplayer.com/product/557363/pokemon-sv07-stellar-crown-stellar-crown-pokemon-center-elite-trainer-box-exclusive-case?Language=all&page=1
...

Sheet Purchase History
A1: PURCHASE HISTORY — Manual entry of all items bought (for P&L cost basis)
A2: Add a row for every purchase. Use the same short_name as the Inventory tab. The P&L tab uses FIFO order (earliest date first) to calculate cost of goods sold.
A3: date | B3: short_name | C3: product_name | D3: quantity | E3: unit_cost | F3: total_cost | G3: notes
A4: Date purchased (MM/DD/YY) | B4: Must match Inventory short_name exactly | C4: Full name (reference only) | D4: Units purchased | E4: Price paid per unit ($) | F4: =D*E (auto) -> #NAME? | G4: Seller, event, condition notes
A5: 01/01/26 | B5: 151 ETB | C5: Scarlet & Violet 151 Elite Trainer Box | D5: 4 | E5: 68 | F5: =D5*E5 -> 272 | G5: Initial stock
A6: 01/01/26 | B6: Evolving Skies Box | C6: Evolving Skies Booster Box | D6: 2 | E6: 200 | F6: =D6*E6 -> 400 | G6: Initial stock
A7: 01/01/26 | B7: Zard 151 SIR | C7: Charizard ex 199/165 SIR | D7: 1 | E7: 144 | F7: =D7*E7 -> 144 | G7: Initial stock NM
A8: 01/01/26 | B8: Pikachu Grey Hat PSA 9 | C8: 2023 Pokemon Van Gogh Pikachu Grey Felt Hat #085 | D8: 1 | E8: 256 | F8: =D8*E8 -> 256 | G8: Initial stock
A9: 01/01/26 | B9: Psyduck Munch PSA 8 | C9: 2018 Pokemon Japanese Psyduck Munch #286SMP | D9: 1 | E9: 76 | F9: =D9*E9 -> 76 | G9: Initial stock
F10: =D10*E10 -> 0
F11: =D11*E11 -> 0
F12: =D12*E12 -> 0
F13: =D13*E13 -> 0
F14: =D14*E14 -> 0
F15: =D15*E15 -> 0
F16: =D16*E16 -> 0
F17: =D17*E17 -> 0
F18: =D18*E18 -> 0
F19: =D19*E19 -> 0
F20: =D20*E20 -> 0
F21: =D21*E21 -> 0
... F34: =D34*E34 -> 0

Sheet P&L
A1: P&L STATEMENT — FIFO Cost Basis (paste Sales Log data below, then update formulas)
A2: Paste your Sales Log export here (columns A-K match the Sales CSV export). Column L calculates FIFO profit using Purchase History. Update the VLOOKUP range as you add purchase data.
A3: HOW TO USE: Export Sales CSV from app → paste starting at row 5 → Column L auto-calculates profit per line item using FIFO avg cost from Purchase History
A4: Transaction # | B4: Date | C4: Time | D4: Item | E4: Qty | F4: Unit Price | G4: Item Discount | H4: Line Total | I4: Cart Discount | J4: Grand Total | K4: Payment | L4: Profit / Loss
A5: Sale ID | B5: Sale date | C5: Sale time | D5: Product sold | E5: Units sold | F5: Sell price each | G5: Per-item disc | H5: Net line revenue | I5: Cart-level disc | J5: Transaction total | K5: Method | L5: FIFO profit (auto)
A6: 032626-001 | B6: 03/26/26 | C6: 10:30 AM | D6: Evolving Skies Box | E6: 1 | F6: 250 | H6: 250 | J6: 250 | K6: Cash | L6: =H6-(E6*IFERROR(AVERAGEIF('Purchase History'!B:B,D6,'Purchase History'!E:E),0)) -> 50
A7: 032626-001 | B7: 03/26/26 | C7: 10:30 AM | D7: 151 ETB | E7: 2 | F7: 85 | H7: 170 | L7: =H7-(E7*IFERROR(AVERAGEIF('Purchase History'!B:B,D7,'Purchase History'!E:E),0)) -> 34
A8: 032626-001 | B8: 03/26/26 | C8: 10:30 AM | D8: [2 items] | I8: 20 | J8: 400
L9: =IF(E9<>"",H9-(E9*IFERROR(AVERAGEIF('Purchase History'!B:B,D9,'Purchase History'!E:E),0)),"")
L10: =IF(E10<>"",H10-(E10*IFERROR(AVERAGEIF('Purchase History'!B:B,D10,'Purchase History'!E:E),0)),"")
L11: =IF(E11<>"",H11-(E11*IFERROR(AVERAGEIF('Purchase History'!B:B,D11,'Purchase History'!E:E),0)),"")
L12: =IF(E12<>"",H12-(E12*IFERROR(AVERAGEIF('Purchase History'!B:B,D12,'Purchase History'!E:E),0)),"")
L13: =IF(E13<>"",H13-(E13*IFERROR(AVERAGEIF('Purchase History'!B:B,D13,'Purchase History'!E:E),0)),"")
L14: =IF(E14<>"",H14-(E14*IFERROR(AVERAGEIF('Purchase History'!B:B,D14,'Purchase History'!E:E),0)),"")
L15: =IF(E15<>"",H15-(E15*IFERROR(AVERAGEIF('Purchase History'!B:B,D15,'Purchase History'!E:E),0)),"")
L16: =IF(E16<>"",H16-(E16*IFERROR(AVERAGEIF('Purchase History'!B:B,D16,'Purchase History'!E:E),0)),"")
L17: =IF(E17<>"",H17-(E17*IFERROR(AVERAGEIF('Purchase History'!B:B,D17,'Purchase History'!E:E),0)),"")
L18: =IF(E18<>"",H18-(E18*IFERROR(AVERAGEIF('Purchase History'!B:B,D18,'Purchase History'!E:E),0)),"")
L19: =IF(E19<>"",H19-(E19*IFERROR(AVERAGEIF('Purchase History'!B:B,D19,'Purchase History'!E:E),0)),"")
L20: =IF(E20<>"",H20-(E20*IFERROR(AVERAGEIF('Purchase History'!B:B,D20,'Purchase History'!E:E),0)),"")
... L38: =IF(E38<>"",H38-(E38*IFERROR(AVERAGEIF('Purchase History'!B:B,D38,'Purchase History'!E:E),0)),"")
A40: SUMMARY
A41: Total Revenue | B41: =SUMIF(E6:E38,">0",H6:H38) -> 0
A42: Total Discounts | B42: =SUMIF(G6:G38,">0",G6:G38)+SUMIF(I6:I38,">0",I6:I38) -> 0
A43: Total Cost (FIFO avg) | B43: =SUMPRODUCT((E6:E38>0)*(E6:E38)*IFERROR(AVERAGEIF('Purchase History'!B:B,D6:D38,'Purchase History'!E:E),0)) -> 0
A44: Gross Profit | B44: =B41-B42-B43 -> 0

Sheet Sales Log
A1: SALES LOG — App syncs here via End Show
A2: Transaction # | B2: Date | C2: Time | D2: Item | E2: Qty | F2: Unit Price | G2: Item Discount | H2: Line Total | I2: Cart Discount | J2: Grand Total | K2: Payment Method(s)
A3: App syncs here via End Show / End Day button. Also paste CSV exports here.

Sheet Buy-Trade Log
A1: BUY/TRADE LOG — App syncs here via End Show
A2: Type | B2: Date | C2: Time | D2: Item | E2: Qty | F2: Value | G2: Price Paid | H2: Notes | I2: Total | J2: Credit Given | K2: Balance Due | L2: Payment | M2: Transaction ID
A3: App syncs here via End Show / End Day button.

Sheet Inventory Snapshot
A1: INVENTORY SNAPSHOT — App pushes end-of-show stock levels here
A2: Snapshot Date | B2: Short Name | C2: Product Name | D2: Set | E2: Type | F2: Qty | G2: Sticker Price | H2: Notes
A3: Each End Show push appends a new snapshot. Keep historic rows to track stock over time.

Sheet Instructions
A1: KITCHEN TCG WORKBOOK GUIDE
A3: SHEET: Inventory | B3: Master source. Fill in your products. avg_purchase_price is calculated automatically from Purchase History — do not edit that column manually. Publish this tab as CSV and sync to the app via Setup → Google Sheets Sync.
A4: SHEET: Purchase History | B4: Manual entry of every item you have bought. Use the same short_name as the Inventory tab. Add a row each time you acquire stock. The P&L tab uses AVERAGEIF across all rows to calculate your average cost per item (approximation of FIFO — for true FIFO use the formula guidance below).
A5: SHEET: P&L | B5: Paste your Sales Log CSV exports here. Column L auto-calculates profit per line using your average purchase cost from Purchase History. Summary section at row 40 shows totals.
A6: P&L Formula (FIFO approx) | B6: The formula =H-((E)*AVERAGEIF('Purchase History'!B:B,D,'Purchase History'!E:E)) gives average cost across all purchases of that item. For strict FIFO, you would track the earliest unallocated purchase cost manually.
A7: SHEET: Sales Log | B7: Populated by app via End Show → Sync. Also paste Sales CSV exports here.
A8: SHEET: Buy-Trade Log | B8: Populated by app via End Show → Sync. Also paste Buy/Trade CSV exports.
A9: SHEET: Inventory Snapshot | B9: Populated by app via End Show → Sync. Each sync appends a new dated snapshot. Keep all rows to track stock over time.
A11: APP: End Show / End Day | B11: In the app: ⚙ Setup → End Show / End Day. Syncs all data to Sheets then clears logs. If sync fails, logs are NOT cleared. You can also clear without syncing as a fallback.
A12: APP: Export CSV | B12: In the app: ⚙ Setup → Export Data section. Downloads Sales, Inventory, and Buy/Trade as separate CSV files without clearing anything.
A13: APP: Sync Inventory from Sheet | B13: Reads your Inventory tab and loads all products + sticker prices into the app. Replaces current inventory.
A14: short_name MATCHING | B14: Purchase History short_name must exactly match Inventory short_name for P&L formulas to work correctly. Case-insensitive in the app but exact in Excel/Sheets formulas.
A15: avg_purchase_price column | B15: This column in Inventory uses: =IFERROR(AVERAGEIF('Purchase History'!B:B,C2,'Purchase History'!E:E),"No purchase data"). Replace C2 with the short_name cell for each row. Copy down as you add items.
A16: SEED DATA NOTE | B16: Purchase History is pre-populated with 1/1/26 entries at 80% of your sticker price as a starting cost basis. Update these with your actual purchase prices as you know them.
